Workbook

Sheet Instrucciones
A1: VALORIX360 · Plantilla de diagnóstico financiero
A2: Liquidez · Flujo de caja · Utilidades · Inventarios · Endeudamiento
A4: CÓMO USAR
A5: 1. Hoja Datos | B5: Digita los estados financieros del cliente en las celdas con texto azul y fondo amarillo (periodo actual y periodo anterior). Los valores precargados son un EJEMPLO: reemplázalos.
A6: 2. Hoja Indicadores | B6: Se calcula sola. Compara contra una referencia editable (celdas azules) y marca cada indicador como Bien o Revisar. Ajusta las referencias al sector del cliente.
A7: Hoja Análisis | B7: Análisis horizontal (variación entre periodos) y vertical (peso de cada cuenta sobre activos o ingresos). Marca las variaciones superiores a 20%.
A8: Hoja Avanzado | B8: Capital de trabajo (KTNO y PKT), DuPont, EBITDA normalizado, últimos 12 meses (LTM), deuda neta, covenants y perfil de vencimientos. Requiere los datos adicionales de la hoja Datos (filas 42 a 60).
A9: Hoja Valor y riesgo | B9: ROIC y EVA frente al costo de capital, puntaje Altman Z'' (mercados emergentes), punto de equilibrio, calidad de utilidades y pruebas de estrés. Requiere los supuestos de la hoja Datos (filas 61 a 67).
A10: Hoja Histórico | B10: Tendencia de 3 años: crecimiento, CAGR, márgenes, conversión a caja y apalancamiento. Se digita con estados de años anteriores.
A11: 3. Hoja Plan de acción | B11: Para cada indicador en Revisar, busca el área correspondiente y selecciona las palancas de mejora.
A12: Unidades | B12: Todo en millones de pesos (COP) salvo que cambies la nota. Los días del periodo se ajustan en Datos (365 para año, 90 para trimestre).
A13: Código de colores | B13: Azul = dato que se digita · Negro = fórmula · Fondo amarillo = celda para completar.
A15: QUÉ PEDIR AL CLIENTE
A16: Estados financieros | B16: Balance general y estado de resultados del periodo actual y del anterior (idealmente 3 años) y flujo de caja o, en su defecto, extractos bancarios del periodo.
A17: Cartera | B17: Cuentas por cobrar por edades (corriente, 30, 60, 90+ días) y concentración por cliente.
A18: Inventarios | B18: Inventario por referencia con rotación, antigüedad y valor; listado de obsoletos o de baja rotación.
A19: Proveedores y deuda | B19: Cuentas por pagar con plazos pactados; tabla de obligaciones financieras (saldo, tasa, plazo, cuota).
A20: Proyecciones | B20: Presupuesto del año, plan de inversiones y estacionalidad de ventas y recaudos.
A22: NOTAS Y SUPUESTOS
A23: Referencias orientativas | B23: Los valores de referencia de la hoja Indicadores son puntos de partida genéricos, no estándares oficiales. Cada sector (comercio, manufactura, servicios) tiene rangos distintos: ajústalos con datos del sector del cliente.
A24: Datos de ejemplo | B24: Cifras ilustrativas creadas por Valorix360 para mostrar el formato esperado; no corresponden a ninguna empresa real.

Sheet Datos
A1: Datos del cliente
A2: Cifras en millones de COP · celdas azules con fondo amarillo = digitar (precargadas con ejemplo)
A4: Concepto | B4: Periodo actual | C4: Periodo anterior | D4: Nota
A6: BALANCE GENERAL
A7: Efectivo y equivalentes | B7: 420 | C7: 380
A8: Cuentas por cobrar (clientes) | B8: 980 | C8: 860
A9: Inventarios | B9: 1350 | C9: 1150
A10: Otros activos corrientes | B10: 150 | C10: 130
A11: Total activo corriente | B11: =B7+B8+B9+B10 -> 2900 | C11: =C7+C8+C9+C10 -> 2520
A12: Activos no corrientes | B12: 2600 | C12: 2500 | D12: Propiedad, planta y equipo, intangibles, etc.
A13: Total activos | B13: =B11+B12 -> 5500 | C13: =C11+C12 -> 5020
A14: Obligaciones financieras de corto plazo | B14: 700 | C14: 650 | D14: Incluye porción corriente de la deuda de largo plazo
A15: Proveedores | B15: 900 | C15: 780
A16: Otros pasivos corrientes | B16: 300 | C16: 270 | D16: Impuestos por pagar, nómina, anticipos
A17: Total pasivo corriente | B17: =B14+B15+B16 -> 1900 | C17: =C14+C15+C16 -> 1700
A18: Pasivo no corriente | B18: 1200 | C18: 1250
A19: Total pasivos | B19: =B17+B18 -> 3100 | C19: =C17+C18 -> 2950
A20: Patrimonio | B20: 2400 | C20: 2070
A21: Control de cuadre (Activos − Pasivos − Patrimonio) | B21: =B13-B19-B20 -> 0 | C21: =C13-C19-C20 -> 0 | D21: Debe dar 0; si no, hay un error de digitación
A23: ESTADO DE RESULTADOS
A24: Ingresos por ventas | B24: 9800 | C24: 8900
A25: Costo de ventas | B25: 6350 | C25: 5870
A26: Gastos operativos (sin depreciación) | B26: 1800 | C26: 1700 | D26: Administración y ventas
A27: Depreciación y amortización | B27: 220 | C27: 210
A28: Gastos financieros | B28: 190 | C28: 180 | D28: Intereses y comisiones
A29: Impuestos | B29: 330 | C29: 280
A30: Utilidad bruta | B30: =B24-B25 -> 3450 | C30: =C24-C25 -> 3030
A31: EBITDA | B31: =B30-B26 -> 1650 | C31: =C30-C26 -> 1330
A32: Utilidad operativa | B32: =B31-B27 -> 1430 | C32: =C31-C27 -> 1120
A33: Utilidad neta | B33: =B32-B28-B29 -> 910 | C33: =C32-C28-C29 -> 660
A35: FLUJO DE CAJA
A36: Flujo de caja operativo | B36: 610 | C36: 540 | D36: Del estado de flujo de efectivo
A37: Inversión en activos fijos (Capex) | B37: 300 | C37: 260
A38: Flujo de caja libre | B38: =B36-B37 -> 310 | C38: =C36-C37 -> 280
A39: Servicio de la deuda (capital + intereses) | B39: 420 | C39: 400 | D39: Pagos del periodo
A40: Días del periodo | B40: 365 | C40: 365 | D40: 365 = año · 90 = trimestre
A42: DATOS ADICIONALES
A43: Deuda financiera de largo plazo | B43: 1200 | C43: 1250 | D43: Obligaciones financieras no corrientes
A44: Gastos no recurrentes (se suman al EBITDA) | B44: 0 | C44: 0 | D44: Provisiones extraordinarias, castigos, gastos únicos (ver notas)
A45: Ingresos no recurrentes (se restan del EBITDA) | B45: 0 | C45: 0 | D45: Venta de activos, recuperaciones, diferencia en cambio
...

Sheet Indicadores
A1: Indicadores del diagnóstico
A2: Se calculan desde la hoja Datos · Referencia (azul) editable según sector
A4: Indicador | B4: Cómo se calcula | C4: Actual | D4: Anterior | E4: Variación | F4: Referencia | G4: Mejor si | H4: Cómo interpretarlo | I4: Estado
A5: LIQUIDEZ
A6: Razón corriente | B6: Activo corriente ÷ Pasivo corriente | C6: =IFERROR(Datos!B11/Datos!B17,0) -> 1.5263158 | D6: =IFERROR(Datos!C11/Datos!C17,0) -> 1.4823529 | E6: =IF(D6=0,0,(C6-D6)/ABS(D6)) -> 0.029657477 | F6: 1.5 | G6: Mayor | H6: Por cada peso de deuda a corto plazo, cuántos pesos de activo corriente hay. Bajo 1,0 hay riesgo de no poder pagar obligaciones inmediatas. | I6: =IF(G6="Mayor",IF(C6>=F6,"Bien","Revisar"),IF(C6<=F6,"Bien","Revisar")) -> Bien
A7: Prueba ácida | B7: (Activo corriente − Inventarios) ÷ Pasivo corriente | C7: =IFERROR((Datos!B11-Datos!B9)/Datos!B17,0) -> 0.81578947 | D7: =IFERROR((Datos!C11-Datos!C9)/Datos!C17,0) -> 0.80588235 | E7: =IF(D7=0,0,(C7-D7)/ABS(D7)) -> 0.012293507 | F7: 1 | G7: Mayor | H7: Liquidez sin depender de vender inventario. Si es muy menor que la razón corriente, la liquidez está atrapada en bodega. | I7: =IF(G7="Mayor",IF(C7>=F7,"Bien","Revisar"),IF(C7<=F7,"Bien","Revisar")) -> Revisar
A8: Capital de trabajo neto ($M) | B8: Activo corriente − Pasivo corriente | C8: =IFERROR(Datos!B11-Datos!B17,0) -> 1000 | D8: =IFERROR(Datos!C11-Datos!C17,0) -> 820 | E8: =IF(D8=0,0,(C8-D8)/ABS(D8)) -> 0.2195122 | F8: 0 | G8: Mayor | H8: Colchón financiero para operar. Negativo implica que se financian activos corrientes con deuda de corto plazo. | I8: =IF(G8="Mayor",IF(C8>=F8,"Bien","Revisar"),IF(C8<=F8,"Bien","Revisar")) -> Bien
A9: Razón de efectivo | B9: Efectivo ÷ Pasivo corriente | C9: =IFERROR(Datos!B7/Datos!B17,0) -> 0.22105263 | D9: =IFERROR(Datos!C7/Datos!C17,0) -> 0.22352941 | E9: =IF(D9=0,0,(C9-D9)/ABS(D9)) -> -0.011080332 | F9: 0.2 | G9: Mayor | H9: Capacidad de pago inmediata solo con caja. | I9: =IF(G9="Mayor",IF(C9>=F9,"Bien","Revisar"),IF(C9<=F9,"Bien","Revisar")) -> Bien
A10: FLUJO DE CAJA
A11: Calidad de utilidades | B11: Flujo operativo ÷ Utilidad neta | C11: =IFERROR(Datos!B36/Datos!B33,0) -> 0.67032967 | D11: =IFERROR(Datos!C36/Datos!C33,0) -> 0.81818182 | E11: =IF(D11=0,0,(C11-D11)/ABS(D11)) -> -0.18070818 | F11: 1 | G11: Mayor | H11: Bajo 1,0 la utilidad contable no se está convirtiendo en caja (cartera e inventario absorben el efectivo). | I11: =IF(G11="Mayor",IF(C11>=F11,"Bien","Revisar"),IF(C11<=F11,"Bien","Revisar")) -> Revisar
A12: Flujo de caja libre ($M) | B12: Flujo operativo − Capex | C12: =IFERROR(Datos!B38,0) -> 310 | D12: =IFERROR(Datos!C38,0) -> 280 | E12: =IF(D12=0,0,(C12-D12)/ABS(D12)) -> 0.10714286 | F12: 0 | G12: Mayor | H12: Caja disponible tras invertir. Negativo sostenido exige deuda o aportes para crecer. | I12: =IF(G12="Mayor",IF(C12>=F12,"Bien","Revisar"),IF(C12<=F12,"Bien","Revisar")) -> Bien
A13: Cobertura del servicio de deuda | B13: Flujo operativo ÷ Servicio de la deuda | C13: =IFERROR(Datos!B36/Datos!B39,0) -> 1.452381 | D13: =IFERROR(Datos!C36/Datos!C39,0) -> 1.35 | E13: =IF(D13=0,0,(C13-D13)/ABS(D13)) -> 0.075837743 | F13: 1.25 | G13: Mayor | H13: Bajo 1,0 el negocio no genera caja suficiente para pagar su deuda; el banco lo mira de primero. | I13: =IF(G13="Mayor",IF(C13>=F13,"Bien","Revisar"),IF(C13<=F13,"Bien","Revisar")) -> Bien
A14: Días de caja | B14: Efectivo ÷ (Costo + Gastos op.) diarios | C14: =IFERROR(Datos!B7/((Datos!B25+Datos!B26)/Datos!B40),0) -> 18.809816 | D14: =IFERROR(Datos!C7/((Datos!C25+Datos!C26)/Datos!C40),0) -> 18.322325 | E14: =IF(D14=0,0,(C14-D14)/ABS(D14)) -> 0.026606393 | F14: 30 | G14: Mayor | H14: Cuántos días podría operar la empresa sin recaudar nada. | I14: =IF(G14="Mayor",IF(C14>=F14,"Bien","Revisar"),IF(C14<=F14,"Bien","Revisar")) -> Revisar
A15: UTILIDADES
A16: Margen bruto | B16: Utilidad bruta ÷ Ingresos | C16: =IFERROR(Datos!B30/Datos!B24,0) -> 0.35204082 | D16: =IFERROR(Datos!C30/Datos!C24,0) -> 0.34044944 | E16: =IF(D16=0,0,(C16-D16)/ABS(D16)) -> 0.034047282 | F16: 0.3 | G16: Mayor | H16: Rentabilidad de producto o servicio antes de gastos. Una caída suele indicar precios bajos o costos de compra altos. | I16: =IF(G16="Mayor",IF(C16>=F16,"Bien","Revisar"),IF(C16<=F16,"Bien","Revisar")) -> Bien
A17: Margen EBITDA | B17: EBITDA ÷ Ingresos | C17: =IFERROR(Datos!B31/Datos!B24,0) -> 0.16836735 | D17: =IFERROR(Datos!C31/Datos!C24,0) -> 0.1494382 | E17: =IF(D17=0,0,(C17-D17)/ABS(D17)) -> 0.12666871 | F17: 0.15 | G17: Mayor | H17: Eficiencia operativa pura, sin efecto de deuda, impuestos ni depreciación. | I17: =IF(G17="Mayor",IF(C17>=F17,"Bien","Revisar"),IF(C17<=F17,"Bien","Revisar")) -> Bien
A18: Margen neto | B18: Utilidad neta ÷ Ingresos | C18: =IFERROR(Datos!B33/Datos!B24,0) -> 0.092857143 | D18: =IFERROR(Datos!C33/Datos!C24,0) -> 0.074157303 | E18: =IF(D18=0,0,(C18-D18)/ABS(D18)) -> 0.2521645 | F18: 0.08 | G18: Mayor | H18: Lo que queda de cada peso vendido tras todos los costos. | I18: =IF(G18="Mayor",IF(C18>=F18,"Bien","Revisar"),IF(C18<=F18,"Bien","Revisar")) -> Bien
A19: ROE (anualizado) | B19: Utilidad neta ÷ Patrimonio × 365 ÷ Días | C19: =IFERROR(Datos!B33/Datos!B20*365/Datos!B40,0) -> 0.37916667 | D19: =IFERROR(Datos!C33/Datos!C20*365/Datos!C40,0) -> 0.31884058 | E19: =IF(D19=0,0,(C19-D19)/ABS(D19)) -> 0.18920455 | F19: 0.12 | G19: Mayor | H19: Retorno para los dueños. Debe superar el costo de oportunidad de su capital. | I19: =IF(G19="Mayor",IF(C19>=F19,"Bien","Revisar"),IF(C19<=F19,"Bien","Revisar")) -> Bien
A20: ROA (anualizado) | B20: Utilidad neta ÷ Activos × 365 ÷ Días | C20: =IFERROR(Datos!B33/Datos!B13*365/Datos!B40,0) -> 0.16545455 | D20: =IFERROR(Datos!C33/Datos!C13*365/Datos!C40,0) -> 0.1314741 | E20: =IF(D20=0,0,(C20-D20)/ABS(D20)) -> 0.2584573 | F20: 0.06 | G20: Mayor | H20: Qué tan bien se usan los activos para generar utilidad. | I20: =IF(G20="Mayor",IF(C20>=F20,"Bien","Revisar"),IF(C20<=F20,"Bien","Revisar")) -> Bien
A21: INVENTARIOS Y CICLO DE CAJA
A22: Rotación de inventarios (anualizada) | B22: Costo de ventas ÷ Inventarios × 365 ÷ Días | C22: =IFERROR(Datos!B25/Datos!B9*365/Datos!B40,0) -> 4.7037037 | D22: =IFERROR(Datos!C25/Datos!C9*365/Datos!C40,0) -> 5.1043478 | E22: =IF(D22=0,0,(C22-D22)/ABS(D22)) -> -0.078490757 | F22: 6 | G22: Mayor | H22: Veces que se renueva el inventario al año. Baja rotación = capital inmovilizado y riesgo de obsolescencia. | I22: =IF(G22="Mayor",IF(C22>=F22,"Bien","Revisar"),IF(C22<=F22,"Bien","Revisar")) -> Revisar
A23: Días de inventario | B23: Inventarios ÷ Costo de ventas × Días | C23: =IFERROR(Datos!B9/Datos!B25*Datos!B40,0) -> 77.598425 | D23: =IFERROR(Datos!C9/Datos!C25*Datos!C40,0) -> 71.507666 | E23: =IF(D23=0,0,(C23-D23)/ABS(D23)) -> 0.085176309 | F23: 60 | G23: Menor | H23: Tiempo promedio que la mercancía espera antes de venderse. | I23: =IF(G23="Mayor",IF(C23>=F23,"Bien","Revisar"),IF(C23<=F23,"Bien","Revisar")) -> Revisar
A24: Días de cartera | B24: Cuentas por cobrar ÷ Ingresos × Días | C24: =IFERROR(Datos!B8/Datos!B24*Datos!B40,0) -> 36.5 | D24: =IFERROR(Datos!C8/Datos!C24*Datos!C40,0) -> 35.269663 | E24: =IF(D24=0,0,(C24-D24)/ABS(D24)) -> 0.034883721 | F24: 45 | G24: Menor | H24: Plazo real de recaudo. Compáralo con el plazo que otorga la empresa. | I24: =IF(G24="Mayor",IF(C24>=F24,"Bien","Revisar"),IF(C24<=F24,"Bien","Revisar")) -> Bien
A25: Días de proveedores | B25: Proveedores ÷ Costo de ventas × Días | C25: =IFERROR(Datos!B15/Datos!B25*Datos!B40,0) -> 51.732283 | D25: =IFERROR(Datos!C15/Datos!C25*Datos!C40,0) -> 48.500852 | E25: =IF(D25=0,0,(C25-D25)/ABS(D25)) -> 0.066626287 | F25: 45 | G25: Mayor | H25: Plazo real de pago. Más plazo ayuda a la caja, pero sin dañar la relación ni perder descuentos. | I25: =IF(G25="Mayor",IF(C25>=F25,"Bien","Revisar"),IF(C25<=F25,"Bien","Revisar")) -> Bien
A26: Ciclo de conversión de efectivo | B26: Días inventario + Días cartera − Días proveedores | C26: =C23+C24-C25 -> 62.366142 | D26: =D23+D24-D25 -> 58.276477 | E26: =IF(D26=0,0,(C26-D26)/ABS(D26)) -> 0.070176934 | F26: 60 | G26: Menor | H26: Días que la empresa financia su operación. Reducirlo libera caja sin pedir deuda. | I26: =IF(G26="Mayor",IF(C26>=F26,"Bien","Revisar"),IF(C26<=F26,"Bien","Revisar")) -> Revisar
A27: ENDEUDAMIENTO
A28: Endeudamiento total | B28: Pasivos totales ÷ Activos totales | C28: =IFERROR(Datos!B19/Datos!B13,0) -> 0.56363636 | D28: =IFERROR(Datos!C19/Datos!C13,0) -> 0.5876494 | E28: =IF(D28=0,0,(C28-D28)/ABS(D28)) -> -0.040862866 | F28: 0.6 | G28: Menor | H28: Proporción de los activos financiada con terceros. | I28: =IF(G28="Mayor",IF(C28>=F28,"Bien","Revisar"),IF(C28<=F28,"Bien","Revisar")) -> Bien
A29: Cobertura de intereses | B29: Utilidad operativa ÷ Gastos financieros | C29: =IFERROR(Datos!B32/Datos!B28,0) -> 7.5263158 | D29: =IFERROR(Datos!C32/Datos!C28,0) -> 6.2222222 | E29: =IF(D29=0,0,(C29-D29)/ABS(D29)) -> 0.20958647 | F29: 3 | G29: Mayor | H29: Qué tanto cubre la utilidad operativa el costo financiero. | I29: =IF(G29="Mayor",IF(C29>=F29,"Bien","Revisar"),IF(C29<=F29,"Bien","Revisar")) -> Bien
A31: Nota: las referencias son orientativas y deben ajustarse al sector del cliente. Variación = cambio relativo frente al periodo anterior.

Sheet Análisis
A1: Análisis horizontal y vertical
A2: Cambio entre periodos y peso de cada cuenta · desde la hoja Datos
A4: Concepto | B4: Actual | C4: Anterior | D4: Variación $M | E4: Variación % | F4: % Actual | G4: % Anterior | H4: Alerta
A5: BALANCE GENERAL · vertical sobre activos totales
A6: Efectivo y equivalentes | B6: =Datos!B7 -> 420 | C6: =Datos!C7 -> 380 | D6: =B6-C6 -> 40 | E6: =IFERROR(D6/ABS(C6),0) -> 0.10526316 | F6: =IFERROR(B6/Datos!B13,0) -> 0.076363636 | G6: =IFERROR(C6/Datos!C13,0) -> 0.075697211 | H6: =IF(ABS(E6)>0.2,"Variación fuerte","")
A7: Cuentas por cobrar | B7: =Datos!B8 -> 980 | C7: =Datos!C8 -> 860 | D7: =B7-C7 -> 120 | E7: =IFERROR(D7/ABS(C7),0) -> 0.13953488 | F7: =IFERROR(B7/Datos!B13,0) -> 0.17818182 | G7: =IFERROR(C7/Datos!C13,0) -> 0.17131474 | H7: =IF(ABS(E7)>0.2,"Variación fuerte","")
A8: Inventarios | B8: =Datos!B9 -> 1350 | C8: =Datos!C9 -> 1150 | D8: =B8-C8 -> 200 | E8: =IFERROR(D8/ABS(C8),0) -> 0.17391304 | F8: =IFERROR(B8/Datos!B13,0) -> 0.24545455 | G8: =IFERROR(C8/Datos!C13,0) -> 0.22908367 | H8: =IF(ABS(E8)>0.2,"Variación fuerte","")
A9: Otros activos corrientes | B9: =Datos!B10 -> 150 | C9: =Datos!C10 -> 130 | D9: =B9-C9 -> 20 | E9: =IFERROR(D9/ABS(C9),0) -> 0.15384615 | F9: =IFERROR(B9/Datos!B13,0) -> 0.027272727 | G9: =IFERROR(C9/Datos!C13,0) -> 0.025896414 | H9: =IF(ABS(E9)>0.2,"Variación fuerte","")
A10: Total activo corriente | B10: =Datos!B11 -> 2900 | C10: =Datos!C11 -> 2520 | D10: =B10-C10 -> 380 | E10: =IFERROR(D10/ABS(C10),0) -> 0.15079365 | F10: =IFERROR(B10/Datos!B13,0) -> 0.52727273 | G10: =IFERROR(C10/Datos!C13,0) -> 0.50199203 | H10: =IF(ABS(E10)>0.2,"Variación fuerte","")
A11: Activos no corrientes | B11: =Datos!B12 -> 2600 | C11: =Datos!C12 -> 2500 | D11: =B11-C11 -> 100 | E11: =IFERROR(D11/ABS(C11),0) -> 0.04 | F11: =IFERROR(B11/Datos!B13,0) -> 0.47272727 | G11: =IFERROR(C11/Datos!C13,0) -> 0.49800797 | H11: =IF(ABS(E11)>0.2,"Variación fuerte","")
A12: Total activos | B12: =Datos!B13 -> 5500 | C12: =Datos!C13 -> 5020 | D12: =B12-C12 -> 480 | E12: =IFERROR(D12/ABS(C12),0) -> 0.09561753 | F12: =IFERROR(B12/Datos!B13,0) -> 1 | G12: =IFERROR(C12/Datos!C13,0) -> 1 | H12: =IF(ABS(E12)>0.2,"Variación fuerte","")
A13: Obligaciones financieras de corto plazo | B13: =Datos!B14 -> 700 | C13: =Datos!C14 -> 650 | D13: =B13-C13 -> 50 | E13: =IFERROR(D13/ABS(C13),0) -> 0.076923077 | F13: =IFERROR(B13/Datos!B13,0) -> 0.12727273 | G13: =IFERROR(C13/Datos!C13,0) -> 0.12948207 | H13: =IF(ABS(E13)>0.2,"Variación fuerte","")
A14: Proveedores | B14: =Datos!B15 -> 900 | C14: =Datos!C15 -> 780 | D14: =B14-C14 -> 120 | E14: =IFERROR(D14/ABS(C14),0) -> 0.15384615 | F14: =IFERROR(B14/Datos!B13,0) -> 0.16363636 | G14: =IFERROR(C14/Datos!C13,0) -> 0.15537849 | H14: =IF(ABS(E14)>0.2,"Variación fuerte","")
A15: Otros pasivos corrientes | B15: =Datos!B16 -> 300 | C15: =Datos!C16 -> 270 | D15: =B15-C15 -> 30 | E15: =IFERROR(D15/ABS(C15),0) -> 0.11111111 | F15: =IFERROR(B15/Datos!B13,0) -> 0.054545455 | G15: =IFERROR(C15/Datos!C13,0) -> 0.053784861 | H15: =IF(ABS(E15)>0.2,"Variación fuerte","")
A16: Total pasivo corriente | B16: =Datos!B17 -> 1900 | C16: =Datos!C17 -> 1700 | D16: =B16-C16 -> 200 | E16: =IFERROR(D16/ABS(C16),0) -> 0.11764706 | F16: =IFERROR(B16/Datos!B13,0) -> 0.34545455 | G16: =IFERROR(C16/Datos!C13,0) -> 0.33864542 | H16: =IF(ABS(E16)>0.2,"Variación fuerte","")
A17: Pasivo no corriente | B17: =Datos!B18 -> 1200 | C17: =Datos!C18 -> 1250 | D17: =B17-C17 -> -50 | E17: =IFERROR(D17/ABS(C17),0) -> -0.04 | F17: =IFERROR(B17/Datos!B13,0) -> 0.21818182 | G17: =IFERROR(C17/Datos!C13,0) -> 0.24900398 | H17: =IF(ABS(E17)>0.2,"Variación fuerte","")
A18: Total pasivos | B18: =Datos!B19 -> 3100 | C18: =Datos!C19 -> 2950 | D18: =B18-C18 -> 150 | E18: =IFERROR(D18/ABS(C18),0) -> 0.050847458 | F18: =IFERROR(B18/Datos!B13,0) -> 0.56363636 | G18: =IFERROR(C18/Datos!C13,0) -> 0.5876494 | H18: =IF(ABS(E18)>0.2,"Variación fuerte","")
A19: Patrimonio | B19: =Datos!B20 -> 2400 | C19: =Datos!C20 -> 2070 | D19: =B19-C19 -> 330 | E19: =IFERROR(D19/ABS(C19),0) -> 0.15942029 | F19: =IFERROR(B19/Datos!B13,0) -> 0.43636364 | G19: =IFERROR(C19/Datos!C13,0) -> 0.4123506 | H19: =IF(ABS(E19)>0.2,"Variación fuerte","")
A21: ESTADO DE RESULTADOS · vertical sobre ingresos
A22: Ingresos por ventas | B22: =Datos!B24 -> 9800 | C22: =Datos!C24 -> 8900 | D22: =B22-C22 -> 900 | E22: =IFERROR(D22/ABS(C22),0) -> 0.1011236 | F22: =IFERROR(B22/Datos!B24,0) -> 1 | G22: =IFERROR(C22/Datos!C24,0) -> 1 | H22: =IF(ABS(E22)>0.2,"Variación fuerte","")
A23: Costo de ventas | B23: =Datos!B25 -> 6350 | C23: =Datos!C25 -> 5870 | D23: =B23-C23 -> 480 | E23: =IFERROR(D23/ABS(C23),0) -> 0.081771721 | F23: =IFERROR(B23/Datos!B24,0) -> 0.64795918 | G23: =IFERROR(C23/Datos!C24,0) -> 0.65955056 | H23: =IF(ABS(E23)>0.2,"Variación fuerte","")
A24: Utilidad bruta | B24: =Datos!B30 -> 3450 | C24: =Datos!C30 -> 3030 | D24: =B24-C24 -> 420 | E24: =IFERROR(D24/ABS(C24),0) -> 0.13861386 | F24: =IFERROR(B24/Datos!B24,0) -> 0.35204082 | G24: =IFERROR(C24/Datos!C24,0) -> 0.34044944 | H24: =IF(ABS(E24)>0.2,"Variación fuerte","")
A25: Gastos operativos (sin D&A) | B25: =Datos!B26 -> 1800 | C25: =Datos!C26 -> 1700 | D25: =B25-C25 -> 100 | E25: =IFERROR(D25/ABS(C25),0) -> 0.058823529 | F25: =IFERROR(B25/Datos!B24,0) -> 0.18367347 | G25: =IFERROR(C25/Datos!C24,0) -> 0.19101124 | H25: =IF(ABS(E25)>0.2,"Variación fuerte","")
A26: EBITDA | B26: =Datos!B31 -> 1650 | C26: =Datos!C31 -> 1330 | D26: =B26-C26 -> 320 | E26: =IFERROR(D26/ABS(C26),0) -> 0.2406015 | F26: =IFERROR(B26/Datos!B24,0) -> 0.16836735 | G26: =IFERROR(C26/Datos!C24,0) -> 0.1494382 | H26: =IF(ABS(E26)>0.2,"Variación fuerte","") -> Variación fuerte
A27: Depreciación y amortización | B27: =Datos!B27 -> 220 | C27: =Datos!C27 -> 210 | D27: =B27-C27 -> 10 | E27: =IFERROR(D27/ABS(C27),0) -> 0.047619048 | F27: =IFERROR(B27/Datos!B24,0) -> 0.02244898 | G27: =IFERROR(C27/Datos!C24,0) -> 0.023595506 | H27: =IF(ABS(E27)>0.2,"Variación fuerte","")
A28: Utilidad operativa | B28: =Datos!B32 -> 1430 | C28: =Datos!C32 -> 1120 | D28: =B28-C28 -> 310 | E28: =IFERROR(D28/ABS(C28),0) -> 0.27678571 | F28: =IFERROR(B28/Datos!B24,0) -> 0.14591837 | G28: =IFERROR(C28/Datos!C24,0) -> 0.1258427 | H28: =IF(ABS(E28)>0.2,"Variación fuerte","") -> Variación fuerte
A29: Gastos financieros | B29: =Datos!B28 -> 190 | C29: =Datos!C28 -> 180 | D29: =B29-C29 -> 10 | E29: =IFERROR(D29/ABS(C29),0) -> 0.055555556 | F29: =IFERROR(B29/Datos!B24,0) -> 0.019387755 | G29: =IFERROR(C29/Datos!C24,0) -> 0.020224719 | H29: =IF(ABS(E29)>0.2,"Variación fuerte","")
A30: Impuestos | B30: =Datos!B29 -> 330 | C30: =Datos!C29 -> 280 | D30: =B30-C30 -> 50 | E30: =IFERROR(D30/ABS(C30),0) -> 0.17857143 | F30: =IFERROR(B30/Datos!B24,0) -> 0.033673469 | G30: =IFERROR(C30/Datos!C24,0) -> 0.031460674 | H30: =IF(ABS(E30)>0.2,"Variación fuerte","")
A31: Utilidad neta | B31: =Datos!B33 -> 910 | C31: =Datos!C33 -> 660 | D31: =B31-C31 -> 250 | E31: =IFERROR(D31/ABS(C31),0) -> 0.37878788 | F31: =IFERROR(B31/Datos!B24,0) -> 0.092857143 | G31: =IFERROR(C31/Datos!C24,0) -> 0.074157303 | H31: =IF(ABS(E31)>0.2,"Variación fuerte","") -> Variación fuerte
A33: FLUJO DE CAJA · vertical sobre ingresos
A34: Flujo de caja operativo | B34: =Datos!B36 -> 610 | C34: =Datos!C36 -> 540 | D34: =B34-C34 -> 70 | E34: =IFERROR(D34/ABS(C34),0) -> 0.12962963 | F34: =IFERROR(B34/Datos!B24,0) -> 0.062244898 | G34: =IFERROR(C34/Datos!C24,0) -> 0.060674157 | H34: =IF(ABS(E34)>0.2,"Variación fuerte","")
A35: Inversión en activos fijos (Capex) | B35: =Datos!B37 -> 300 | C35: =Datos!C37 -> 260 | D35: =B35-C35 -> 40 | E35: =IFERROR(D35/ABS(C35),0) -> 0.15384615 | F35: =IFERROR(B35/Datos!B24,0) -> 0.030612245 | G35: =IFERROR(C35/Datos!C24,0) -> 0.029213483 | H35: =IF(ABS(E35)>0.2,"Variación fuerte","")
A36: Flujo de caja libre | B36: =Datos!B38 -> 310 | C36: =Datos!C38 -> 280 | D36: =B36-C36 -> 30 | E36: =IFERROR(D36/ABS(C36),0) -> 0.10714286 | F36: =IFERROR(B36/Datos!B24,0) -> 0.031632653 | G36: =IFERROR(C36/Datos!C24,0) -> 0.031460674 | H36: =IF(ABS(E36)>0.2,"Variación fuerte","")
A38: En cortes intermedios el balance se compara contra el cierre anterior y el estado de resultados contra el mismo periodo del año previo. Variación fuerte = cambio superior a 20%.

Sheet Avanzado
A1: Análisis avanzado
A2: Capital de trabajo · DuPont · EBITDA normalizado · LTM · Deuda y covenants
A4: Concepto | B4: Actual | C4: Anterior | D4: Cómo leerlo
A5: CAPITAL DE TRABAJO NETO OPERATIVO (KTNO)
A6: KTNO = Cartera + Inventarios − Proveedores | B6: =Datos!B8+Datos!B9-Datos!B15 -> 1430 | C6: =Datos!C8+Datos!C9-Datos!C15 -> 1230 | D6: Dinero que la operación mantiene inmovilizado para vender a crédito y tener inventario.
A7: Ventas anualizadas | B7: =Datos!B24*365/Datos!B40 -> 9800 | C7: =Datos!C24*365/Datos!C40 -> 8900 | D7: Ingresos del periodo llevados a 12 meses con los días del periodo.
A8: PKT = KTNO ÷ Ventas anualizadas | B8: =IFERROR(B6/B7,0) -> 0.14591837 | C8: =IFERROR(C6/C7,0) -> 0.13820225 | D8: Centavos de caja que cada peso de ventas mantiene atrapados en la operación. Menor es mejor.
A9: KTNO en días de ventas | B9: =B8*365 -> 53.260204 | C9: =C8*365 -> 50.44382 | D9: Días de ventas que equivale el capital de trabajo operativo.
A10: Caja consumida por cada $1 de crecimiento de ventas | B10: =IFERROR((B6-C6)/(B7-C7),0) -> 0.22222222 | D10: Si supera el PKT, crecer está consumiendo más caja que el promedio del negocio.
A12: DUPONT · de dónde viene el retorno (anualizado)
A13: Margen neto | B13: =IFERROR(Datos!B33/Datos!B24,0) -> 0.092857143 | C13: =IFERROR(Datos!C33/Datos!C24,0) -> 0.074157303 | D13: Eficiencia: cuánto queda de cada peso vendido.
A14: Rotación de activos | B14: =IFERROR(B7/Datos!B13,0) -> 1.7818182 | C14: =IFERROR(C7/Datos!C13,0) -> 1.7729084 | D14: Productividad: cuántos pesos de ventas genera cada peso de activos.
A15: Apalancamiento (Activos ÷ Patrimonio) | B15: =IFERROR(Datos!B13/Datos!B20,0) -> 2.2916667 | C15: =IFERROR(Datos!C13/Datos!C20,0) -> 2.4251208 | D15: Cuánto del retorno se debe a financiarse con deuda.
A16: ROE = Margen × Rotación × Apalancamiento | B16: =B13*B14*B15 -> 0.37916667 | C16: =C13*C14*C15 -> 0.31884058 | D16: Si el ROE depende sobre todo del apalancamiento, el retorno es más frágil.
A18: EBITDA NORMALIZADO
A19: EBITDA reportado | B19: =Datos!B31 -> 1650 | C19: =Datos!C31 -> 1330
A20: (+) Gastos no recurrentes | B20: =Datos!B44 -> 0 | C20: =Datos!C44 -> 0 | D20: Provisiones o gastos únicos: se suman.
A21: (−) Ingresos no recurrentes | B21: =Datos!B45 -> 0 | C21: =Datos!C45 -> 0 | D21: Ingresos únicos: se restan.
A22: EBITDA normalizado | B22: =B19+B20-B21 -> 1650 | C22: =C19+C20-C21 -> 1330 | D22: Base más fiel de la capacidad recurrente de generar caja.
A23: Margen EBITDA normalizado | B23: =IFERROR(B22/Datos!B24,0) -> 0.16836735 | C23: =IFERROR(C22/Datos!C24,0) -> 0.1494382
A25: ÚLTIMOS 12 MESES (LTM) · Actual = LTM · Anterior = año completo anterior
A26: Ingresos | B26: =IF(Datos!B40>=365,Datos!B24,IF(Datos!B47="","n/d",Datos!B47+Datos!B24-Datos!C24)) -> 9800 | C26: =IF(Datos!B47="","n/d",Datos!B47) -> 9300 | D26: LTM = año anterior + acumulado actual − acumulado del mismo periodo anterior. Evita comparar medio año con año completo.
A27: EBITDA | B27: =IF(Datos!B40>=365,Datos!B31,IF(OR(Datos!B47="",Datos!B48="",Datos!B49=""),"n/d",(Datos!B47-Datos!B48-Datos!B49)+Datos!B31-Datos!C31)) -> 1650 | C27: =IF(OR(Datos!B47="",Datos!B48="",Datos!B49=""),"n/d",Datos!B47-Datos!B48-Datos!B49) -> 1660 | D27: Base para los indicadores de deuda cuando el corte es intermedio.
A28: Flujo de caja operativo | B28: =IF(Datos!B40>=365,Datos!B36,IF(Datos!B51="","n/d",Datos!B51+Datos!B36-Datos!C36)) -> 610 | C28: =IF(Datos!B51="","n/d",Datos!B51) -> 640
A29: Utilidad neta | B29: =IF(Datos!B40>=365,Datos!B33,IF(Datos!B52="","n/d",Datos!B52+Datos!B33-Datos!C33)) -> 910 | C29: =IF(Datos!B52="","n/d",Datos!B52) -> 660
A30: Margen EBITDA LTM | B30: =IFERROR(B27/B26,"n/d") -> 0.16836735 | C30: =IFERROR(C27/C26,"n/d") -> 0.17849462
A32: DEUDA FINANCIERA
A33: Deuda de corto plazo | B33: =Datos!B14 -> 700 | C33: =Datos!C14 -> 650
A34: Deuda de largo plazo | B34: =Datos!B43 -> 1200 | C34: =Datos!C43 -> 1250
A35: Deuda financiera total | B35: =B33+B34 -> 1900 | C35: =C33+C34 -> 1900
A36: Deuda neta (deuda − efectivo) | B36: =B35-Datos!B7 -> 1480 | C36: =C35-Datos!C7 -> 1520
A37: Deuda neta ÷ EBITDA (LTM) | B37: =IFERROR(B36/B27,"n/d") -> 0.8969697 | C37: =IFERROR(C36/C27,"n/d") -> 0.91566265 | D37: Años de EBITDA que tomaría pagar la deuda neta. Los bancos suelen mirar este indicador de primero.
A38: Deuda total ÷ EBITDA (LTM) | B38: =IFERROR(B35/B27,"n/d") -> 1.1515152 | C38: =IFERROR(C35/C27,"n/d") -> 1.1445783
A39: Cobertura del servicio de la deuda (flujo operativo ÷ pagos) | B39: =IFERROR(Datos!B36/Datos!B39,"n/d") -> 1.452381 | C39: =IFERROR(Datos!C36/Datos!C39,"n/d") -> 1.35 | D39: Bajo 1,0x el negocio no genera caja suficiente para atender su deuda.
A40: Costo promedio de la deuda (anualizado) | B40: =IFERROR(Datos!B28*365/Datos!B40/AVERAGE(B35,C35),"n/d") -> 0.1 | D40: Gastos financieros anualizados ÷ deuda promedio. Compáralo con la tasa vigente del mercado.
A41: % de la deuda en corto plazo | B41: =IFERROR(B33/B35,0) -> 0.36842105 | C41: =IFERROR(C33/C35,0) -> 0.34210526 | D41: Una proporción alta presiona la caja del próximo año.
A42: Endeudamiento total (Pasivos ÷ Activos) | B42: =IFERROR(Datos!B19/Datos!B13,0) -> 0.56363636 | C42: =IFERROR(Datos!C19/Datos!C13,0) -> 0.5876494
A44: PRUEBA DE COVENANTS
A45: Covenant | B45: Actual | C45: Límite pactado | D45: Resultado
A46: Endeudamiento total (máximo) | B46: =B42 -> 0.56363636 | C46: =IF(Datos!B54="","",Datos!B54) -> 0.65 | D46: =IF(OR(C46="",NOT(ISNUMBER(B46))),"Sin dato",IF(B46<=C46,"Cumple · holgura "&TEXT(C46-B46,"0.0%"),"INCUMPLE")) -> Cumple · holgura 8.6%
...

Sheet Valor y riesgo
A1: Valor y riesgo
A2: ROIC y EVA · Altman Z'' · Punto de equilibrio · Calidad de utilidades · Pruebas de estrés
A4: Concepto | B4: Actual | C4: Anterior | D4: Cómo leerlo
A5: CREACIÓN DE VALOR · ROIC y EVA
A6: Utilidad operativa anualizada | B6: =Datos!B32*365/Datos!B40 -> 1430 | C6: =Datos!C32*365/Datos!C40 -> 1120 | D6: EBIT llevado a 12 meses con los días del periodo.
A7: Tasa efectiva de impuestos | B7: =IFERROR(Datos!B29/(Datos!B32-Datos!B28),0) -> 0.26612903 | C7: =IFERROR(Datos!C29/(Datos!C32-Datos!C28),0) -> 0.29787234 | D7: Impuestos ÷ utilidad antes de impuestos.
A8: NOPAT (utilidad operativa después de impuestos) | B8: =B6*(1-B7) -> 1049.4355 | C8: =C6*(1-C7) -> 786.38298
A9: Capital invertido (patrimonio + deuda financiera − efectivo) | B9: =Datos!B20+Avanzado!B35-Datos!B7 -> 3880 | C9: =Datos!C20+Avanzado!C35-Datos!C7 -> 3590 | D9: Capital que financia la operación.
A10: ROIC | B10: =IFERROR(B8/B9,0) -> 0.27047306 | C10: =IFERROR(C8/C9,0) -> 0.21904818 | D10: Retorno de la operación sobre el capital invertido.
A11: Peso de la deuda en el capital | B11: =IFERROR(Avanzado!B35/(Avanzado!B35+Datos!B20),0) -> 0.44186047 | C11: =IFERROR(Avanzado!C35/(Avanzado!C35+Datos!C20),0) -> 0.47858942
A12: Costo de la deuda (Kd) | B12: =Avanzado!B40 -> 0.1 | D12: Del análisis de deuda: gastos financieros ÷ deuda promedio.
A13: WACC (costo promedio de capital) | B13: =IF(OR(Datos!B63="",NOT(ISNUMBER(B12))),"n/d",(1-B11)*Datos!B63+B11*B12*(1-B7)) -> 0.13289197 | D13: Requiere el costo del patrimonio (Ke) en la hoja Datos.
A14: Spread (ROIC − WACC) | B14: =IF(ISNUMBER(B13),B10-B13,"n/d") -> 0.13758109 | D14: Positivo: la empresa crea valor. Negativo: lo destruye aunque tenga utilidad contable.
A15: EVA ($M anualizado) | B15: =IF(ISNUMBER(B14),B14*B9,"n/d") -> 533.81463 | D15: Valor económico creado después de remunerar a deuda y patrimonio.
A17: RIESGO DE QUIEBRA · Altman Z'' (mercados emergentes)
A18: X1 · Capital de trabajo ÷ Activos | B18: =IFERROR((Datos!B11-Datos!B17)/Datos!B13,0) -> 0.18181818 | C18: =IFERROR((Datos!C11-Datos!C17)/Datos!C13,0) -> 0.16334661 | D18: Liquidez.
A19: X2 · Utilidades retenidas ÷ Activos | B19: =IF(Datos!B62="","n/d",IFERROR((Datos!B20-Datos!B62)/Datos!B13,0)) -> 0.29090909 | C19: =IF(Datos!C62="","n/d",IFERROR((Datos!C20-Datos!C62)/Datos!C13,0)) -> 0.25298805 | D19: Utilidades retenidas estimadas como patrimonio − capital social.
A20: X3 · EBIT anualizado ÷ Activos | B20: =IFERROR(B6/Datos!B13,0) -> 0.26 | C20: =IFERROR(C6/Datos!C13,0) -> 0.22310757 | D20: Rentabilidad operativa.
A21: X4 · Patrimonio ÷ Pasivos | B21: =IFERROR(Datos!B20/Datos!B19,0) -> 0.77419355 | C21: =IFERROR(Datos!C20/Datos!C19,0) -> 0.70169492 | D21: Solvencia.
A22: Z'' = 3,25 + 6,56·X1 + 3,26·X2 + 6,72·X3 + 1,05·X4 | B22: =IF(ISNUMBER(B19),3.25+6.56*B18+3.26*B19+6.72*B20+1.05*B21,"n/d") -> 7.9511941 | C22: =IF(ISNUMBER(C19),3.25+6.56*C18+3.26*C19+6.72*C20+1.05*C21,"n/d") -> 7.3823574 | D22: Mayor a 5,85 zona segura; entre 4,15 y 5,85 zona gris; menor a 4,15 zona de riesgo.
A23: Zona | B23: =IF(ISNUMBER(B22),IF(B22>5.85,"Zona segura",IF(B22>=4.15,"Zona gris","Zona de riesgo")),"n/d") -> Zona segura | C23: =IF(ISNUMBER(C22),IF(C22>5.85,"Zona segura",IF(C22>=4.15,"Zona gris","Zona de riesgo")),"n/d") -> Zona segura | D23: Referencia académica: úsala como señal de alerta, no como sentencia.
A25: PUNTO DE EQUILIBRIO (supuesto: costo de ventas variable; gastos operativos, D&A y financieros fijos)
A26: Margen de contribución | B26: =IFERROR((Datos!B24-Datos!B25)/Datos!B24,0) -> 0.35204082 | C26: =IFERROR((Datos!C24-Datos!C25)/Datos!C24,0) -> 0.34044944 | D26: Lo que cada peso vendido aporta para cubrir costos fijos.
A27: Costos fijos anualizados | B27: =(Datos!B26+Datos!B27+Datos!B28)*365/Datos!B40 -> 2210 | C27: =(Datos!C26+Datos!C27+Datos!C28)*365/Datos!C40 -> 2090
A28: Ventas de equilibrio (anualizadas) | B28: =IFERROR(B27/B26,"n/d") -> 6277.6812 | C28: =IFERROR(C27/C26,"n/d") -> 6138.9439 | D28: Ventas mínimas para no perder.
A29: Margen de seguridad | B29: =IFERROR((Avanzado!B7-B28)/Avanzado!B7,"n/d") -> 0.35942029 | C29: =IFERROR((Avanzado!C7-C28)/Avanzado!C7,"n/d") -> 0.31023102 | D29: Cuánto pueden caer las ventas antes de entrar en pérdida.
A30: Grado de apalancamiento operativo | B30: =IFERROR(Avanzado!B7*B26/B6,"n/d") -> 2.4125874 | C30: =IFERROR(Avanzado!C7*C26/C6,"n/d") -> 2.7053571 | D30: Veces que cambia la utilidad operativa por cada cambio de 1% en ventas.
A32: CALIDAD DE UTILIDADES
A33: Accruals (utilidad neta − flujo operativo) ÷ Activos | B33: =IFERROR((Datos!B33-Datos!B36)/Datos!B13,0) -> 0.054545455 | C33: =IFERROR((Datos!C33-Datos!C36)/Datos!C13,0) -> 0.023904382 | D33: Alto y positivo: la utilidad contable no se está convirtiendo en caja.
A34: Conversión: flujo de caja libre ÷ utilidad neta | B34: =IFERROR(Datos!B38/Datos!B33,0) -> 0.34065934 | C34: =IFERROR(Datos!C38/Datos!C33,0) -> 0.42424242
A35: Tasa efectiva menos tasa nominal de renta | B35: =B7-Datos!B64 -> -0.083870968 | D35: Una diferencia grande merece revisión en las notas de impuestos (diferidos, descuentos, pérdidas fiscales).
A37: PRUEBAS DE ESTRÉS · Base frente a escenario adverso
A38: Concepto | B38: Base | C38: Estrés | D38: Supuestos (editables en la hoja Datos, filas 65 a 67)
A39: Ventas anualizadas | B39: =Avanzado!B7 -> 9800 | C39: =Avanzado!B7*(1-Datos!B65) -> 8330 | D39: Caída de ventas del escenario.
A40: EBITDA anualizado | B40: =(Datos!B24-Datos!B25-Datos!B26)*365/Datos!B40 -> 1650 | C40: =C39*B26-Datos!B26*365/Datos!B40 -> 1132.5 | D40: Los gastos operativos se mantienen fijos; el costo de ventas baja con las ventas.
A41: Utilidad operativa anualizada | B41: =B6 -> 1430 | C41: =C40-Datos!B27*365/Datos!B40 -> 912.5
A42: Gastos financieros anualizados | B42: =Datos!B28*365/Datos!B40 -> 190 | C42: =B42+Avanzado!B35*Datos!B66 -> 247 | D42: Suma el efecto de la alza de tasa sobre toda la deuda.
A43: Cobertura de intereses (utilidad operativa ÷ gastos financieros) | B43: =IFERROR(B41/B42,"n/d") -> 7.5263158 | C43: =IFERROR(C41/C42,"n/d") -> 3.694332 | D43: Bajo 1,5x el negocio queda muy expuesto.
A44: Deuda neta ÷ EBITDA | B44: =IFERROR(Avanzado!B36/B40,"n/d") -> 0.8969697 | C44: =IF(C40<=0,"n/d",Avanzado!B36/C40) -> 1.3068433
A45: Caja absorbida por mayor plazo de cartera | C45: =C39/365*Datos!B67 -> 342.32877 | D45: Dinero adicional que quedaría inmovilizado en cartera.
...

Sheet Histórico
A1: Histórico de 3 años
A2: Se digita con los estados de años anteriores (millones de COP) · datos de ejemplo
A3: Año (editable) →
A4: Concepto | B4: 2023 | C4: 2024 | D4: 2025 | E4: Tendencia / CAGR
A5: DATOS ANUALES
A6: Ingresos | B6: 8100 | C6: 8700 | D6: 9300 | E6: =IFERROR(IF(D6>B6,"↑ ","↓ ")&TEXT((D6/B6)^(1/(D$4-B$4))-1,"0.0%")&" anual (CAGR)","") -> ↑ 7.2% anual (CAGR)
A7: Utilidad bruta | B7: 2650 | C7: 2900 | D7: 3220 | E7: =IFERROR(IF(D7>B7,"↑ ","↓ ")&TEXT((D7/B7)^(1/(D$4-B$4))-1,"0.0%")&" anual (CAGR)","") -> ↑ 10.2% anual (CAGR)
A8: EBITDA | B8: 1150 | C8: 1400 | D8: 1660 | E8: =IFERROR(IF(D8>B8,"↑ ","↓ ")&TEXT((D8/B8)^(1/(D$4-B$4))-1,"0.0%")&" anual (CAGR)","") -> ↑ 20.1% anual (CAGR)
A9: Utilidad neta | B9: 520 | C9: 590 | D9: 660 | E9: =IFERROR(IF(D9>B9,"↑ ","↓ ")&TEXT((D9/B9)^(1/(D$4-B$4))-1,"0.0%")&" anual (CAGR)","") -> ↑ 12.7% anual (CAGR)
A10: Flujo de caja operativo | B10: 480 | C10: 520 | D10: 640 | E10: =IFERROR(IF(D10>B10,"↑ ","↓ ")&TEXT((D10/B10)^(1/(D$4-B$4))-1,"0.0%")&" anual (CAGR)","") -> ↑ 15.5% anual (CAGR)
A11: Efectivo | B11: 310 | C11: 340 | D11: 380 | E11: =IFERROR(IF(D11>B11,"↑ ","↓ ")&TEXT((D11/B11)^(1/(D$4-B$4))-1,"0.0%")&" anual (CAGR)","") -> ↑ 10.7% anual (CAGR)
A12: Activos totales | B12: 4600 | C12: 4800 | D12: 5020 | E12: =IFERROR(IF(D12>B12,"↑ ","↓ ")&TEXT((D12/B12)^(1/(D$4-B$4))-1,"0.0%")&" anual (CAGR)","") -> ↑ 4.5% anual (CAGR)
A13: Deuda financiera | B13: 1900 | C13: 1950 | D13: 1900 | E13: =IFERROR(IF(D13>B13,"↑ ","↓ ")&TEXT((D13/B13)^(1/(D$4-B$4))-1,"0.0%")&" anual (CAGR)","") -> ↓ 0.0% anual (CAGR)
A14: Patrimonio | B14: 1700 | C14: 1850 | D14: 2070 | E14: =IFERROR(IF(D14>B14,"↑ ","↓ ")&TEXT((D14/B14)^(1/(D$4-B$4))-1,"0.0%")&" anual (CAGR)","") -> ↑ 10.3% anual (CAGR)
A16: INDICADORES CALCULADOS
A17: Crecimiento anual de ingresos | C17: =IFERROR(C6/B6-1,0) -> 0.074074074 | D17: =IFERROR(D6/C6-1,0) -> 0.068965517 | E17: =IF(D17>C17,"Mejora","Deterioro")&" frente a "&C$4 -> Deterioro frente a 2024
A18: Margen bruto | B18: =IFERROR(B7/B6,0) -> 0.32716049 | C18: =IFERROR(C7/C6,0) -> 0.33333333 | D18: =IFERROR(D7/D6,0) -> 0.34623656 | E18: =IFERROR(IF(D18>B18,"Mejora","Deterioro")&" frente a "&B$4,"") -> Mejora frente a 2023
A19: Margen EBITDA | B19: =IFERROR(B8/B6,0) -> 0.14197531 | C19: =IFERROR(C8/C6,0) -> 0.16091954 | D19: =IFERROR(D8/D6,0) -> 0.17849462 | E19: =IFERROR(IF(D19>B19,"Mejora","Deterioro")&" frente a "&B$4,"") -> Mejora frente a 2023
A20: Margen neto | B20: =IFERROR(B9/B6,0) -> 0.064197531 | C20: =IFERROR(C9/C6,0) -> 0.067816092 | D20: =IFERROR(D9/D6,0) -> 0.070967742 | E20: =IFERROR(IF(D20>B20,"Mejora","Deterioro")&" frente a "&B$4,"") -> Mejora frente a 2023
A21: Conversión a caja (flujo operativo ÷ utilidad neta) | B21: =IFERROR(B10/B9,0) -> 0.92307692 | C21: =IFERROR(C10/C9,0) -> 0.88135593 | D21: =IFERROR(D10/D9,0) -> 0.96969697 | E21: =IFERROR(IF(D21>B21,"Mejora","Deterioro")&" frente a "&B$4,"") -> Mejora frente a 2023
A22: ROE | B22: =IFERROR(B9/B14,0) -> 0.30588235 | C22: =IFERROR(C9/C14,0) -> 0.31891892 | D22: =IFERROR(D9/D14,0) -> 0.31884058 | E22: =IFERROR(IF(D22>B22,"Mejora","Deterioro")&" frente a "&B$4,"") -> Mejora frente a 2023
A23: Deuda neta ÷ EBITDA | B23: =IFERROR((B13-B11)/B8,0) -> 1.3826087 | C23: =IFERROR((C13-C11)/C8,0) -> 1.15 | D23: =IFERROR((D13-D11)/D8,0) -> 0.91566265 | E23: =IFERROR(IF(D23<B23,"Mejora","Deterioro")&" frente a "&B$4,"") -> Mejora frente a 2023
A25: Para el último año usa el cierre anual (no el corte intermedio). Las cifras de ejemplo son ilustrativas.

Sheet Plan de acción
A1: Plan de acción por área
A2: Palancas de mejora según la señal de alerta detectada en Indicadores
A4: Área | B4: Señal de alerta | C4: Acciones recomendadas | D4: Impacto esperado
A5: Liquidez | B5: Razón corriente baja, capital de trabajo negativo o prueba ácida muy inferior a la razón corriente | C5: Pasar deuda de corto a largo plazo; abrir una línea de crédito rotativa; liberar caja de cartera e inventario; posponer inversiones no críticas. | D5: Mayor holgura para pagar obligaciones y menos riesgo de iliquidez.
A6: Flujo de caja | B6: Flujo operativo menor que la utilidad neta, o cobertura de deuda cercana a 1 | C6: Política de cobro (descuento por pronto pago, facturación anticipada, cobro por edades); negociar plazos con proveedores; proyección de caja semanal a 13 semanas. | D6: Utilidad que sí se convierte en efectivo; menos dependencia del crédito.
A7: Cartera | B7: Días de cartera por encima del plazo otorgado o concentración en pocos clientes | C7: Segmentar clientes por riesgo; cupos de crédito; gestión de cobro proactiva; factoring selectivo; diversificar la base de clientes. | D7: Menor ciclo de caja y menor pérdida por incobrables.
A8: Inventarios | B8: Días de inventario altos, rotación baja, referencias obsoletas | C8: Clasificación ABC; liquidar obsoletos; puntos de reorden y stock de seguridad; compras ligadas a demanda proyectada; consignación con proveedores clave. | D8: Capital liberado y menores costos de bodegaje y obsolescencia.
A9: Utilidades | B9: Margen bruto o EBITDA en caída frente al periodo anterior | C9: Revisar precios y mezcla de productos; renegociar costos de compra; análisis de rentabilidad por cliente y producto; recortar gastos no esenciales. | D9: Mejor margen sin depender solo de vender más.
A10: Endeudamiento | B10: Endeudamiento sobre la referencia o cobertura de intereses baja | C10: Reperfilar la deuda (plazo y tasa); capitalizar utilidades; prepagar la deuda más cara; evitar deuda de corto plazo para activos de largo plazo. | D10: Menor costo financiero y mayor capacidad de crédito futura.
